<mujoco model="wujihand-right">
  <compiler angle="radian" meshdir="meshes/right/" />
  <option gravity="0 0 -9.81" jacobian="sparse" integrator="implicit" timestep="0.002" solver="Newton" iterations="50" tolerance="1e-10" />
  <statistic center="0 0 0.1" extent="0.35" />

  <visual>
    <headlight diffuse="0.6 0.6 0.6" ambient="0.3 0.3 0.3" specular="0 0 0" />
    <rgba haze="0.15 0.25 0.35 1" />
    <global azimuth="120" elevation="-25" />
  </visual>

  <default>
    <joint armature="0.0002" damping="0.0" />
  </default>
  <asset>
    <mesh name="r_base_link" content_type="model/stl" file="r_base_link.STL" />
    <mesh name="r_thumb_proximal" content_type="model/stl" file="r_thumb_proximal.STL" />
    <mesh name="r_thumb_proximal_abd" content_type="model/stl" file="r_thumb_proximal_abd.STL" />
    <mesh name="r_thumb_middle" content_type="model/stl" file="r_thumb_middle.STL" />
    <mesh name="r_thumb_distal" content_type="model/stl" file="r_thumb_distal.STL" />
    <mesh name="r_index_finger_proximal" content_type="model/stl" file="r_index_finger_proximal.STL" />
    <mesh name="r_index_finger_proximal_abd" content_type="model/stl" file="r_index_finger_proximal_abd.STL" />
    <mesh name="r_index_finger_middle" content_type="model/stl" file="r_index_finger_middle.STL" />
    <mesh name="r_index_finger_distal" content_type="model/stl" file="r_index_finger_distal.STL" />
    <mesh name="r_middle_finger_proximal" content_type="model/stl" file="r_middle_finger_proximal.STL" />
    <mesh name="r_middle_finger_proximal_abd" content_type="model/stl" file="r_middle_finger_proximal_abd.STL" />
    <mesh name="r_middle_finger_middle" content_type="model/stl" file="r_middle_finger_middle.STL" />
    <mesh name="r_middle_finger_distal" content_type="model/stl" file="r_middle_finger_distal.STL" />
    <mesh name="r_ring_finger_proximal" content_type="model/stl" file="r_ring_finger_proximal.STL" />
    <mesh name="r_ring_finger_proximal_abd" content_type="model/stl" file="r_ring_finger_proximal_abd.STL" />
    <mesh name="r_ring_finger_middle" content_type="model/stl" file="r_ring_finger_middle.STL" />
    <mesh name="r_ring_finger_distal" content_type="model/stl" file="r_ring_finger_distal.STL" />
    <mesh name="r_pinky_proximal" content_type="model/stl" file="r_pinky_proximal.STL" />
    <mesh name="r_pinky_proximal_abd" content_type="model/stl" file="r_pinky_proximal_abd.STL" />
    <mesh name="r_pinky_middle" content_type="model/stl" file="r_pinky_middle.STL" />
    <mesh name="r_pinky_distal" content_type="model/stl" file="r_pinky_distal.STL" />
    <mesh name="r_wrist" content_type="model/stl" file="r_wrist.STL" />
  </asset>
  <worldbody>
    <body name="r_base_link" gravcomp="1" pos="0.05 0 0.43" quat="0.7071068 0 0.7071068 0">
      <joint name="base_free" type="free" damping="1" />
      <inertial pos="-0.00272850775526 -0.00107303771526 0.0533827160948" mass="0.3013" quat="0.03384030 0.01041875 0.99905755 -0.02510550" diaginertia="2.99905109e-04 2.36568961e-04 1.02188510e-04" />
      <geom type="mesh" contype="0" conaffinity="0" group="1" density="0" rgba="0.6 0.8 0.9 1" mesh="r_base_link" />
      <geom type="mesh" rgba="0.6 0.8 0.9 1" mesh="r_base_link" contype="1" conaffinity="1" />
      <geom pos="0.000250158 0.00300004 0.0284999" type="mesh" contype="0" conaffinity="0" group="1" density="0" rgba="0.6 0.8 0.9 1" mesh="r_wrist" />
      <geom pos="0.000250158 0.00300004 0.0284999" type="mesh" rgba="0.6 0.8 0.9 1" mesh="r_wrist" contype="1" conaffinity="1" />
      <body name="r_thumb_proximal" gravcomp="1" pos="0.00838841 0.0202095 0.0449574" quat="0.629428 -0.720111 -0.0606284 -0.285631">
        <inertial pos="-0.00195618 0.000853657 0.00731809" quat="0.395273 -0.0427462 0.0680097 0.915045" mass="0.011" diaginertia="8.38654e-07 7.81045e-07 6.3308e-07" />
        <joint name="r_thumb_cmc_flex" pos="0 0 0" axis="0 1 0" range="-1.187 1.291" actuatorfrcrange="-0.6 0.6" armature="0.0005" />
        <geom type="mesh" contype="0" conaffinity="0" group="1" density="0" rgba="0.7 0.7 0.7 1" mesh="r_thumb_proximal" />
        <geom type="mesh" rgba="0.7 0.7 0.7 1" mesh="r_thumb_proximal" contype="0" conaffinity="0" />
        <body name="r_thumb_proximal_abd" gravcomp="1" pos="-0.00053658 0.000247879 0.0147535" quat="0.677463 0.177193 0.307201 -0.644417">
          <inertial pos="-1.27934e-05 6.47331e-06 0.0130544" quat="0.857754 -0.00239204 -0.00124335 0.514054" mass="0.0336" diaginertia="4.2288e-06 4.08475e-06 1.2356e-06" />
          <joint name="r_thumb_cmc_abd" pos="0 0 0" axis="0 1 0" range="-1.484 0.698" actuatorfrcrange="-0.6 0.6" armature="0.0005" />
          <geom type="mesh" contype="0" conaffinity="0" group="1" density="0" rgba="0.9 0.8 0.6 1" mesh="r_thumb_proximal_abd" />
          <geom type="mesh" rgba="0.9 0.8 0.6 1" mesh="r_thumb_proximal_abd" contype="2" conaffinity="2" />
          <body name="r_thumb_middle" gravcomp="1" pos="0 0 0.0325" quat="0.875892 0.0382423 0.0209804 0.480531">
            <inertial pos="4.31169e-08 -4.92924e-05 0.0143056" quat="0.999999 -4.68311e-05 6.69742e-07 -0.00118251" mass="0.0358" diaginertia="4.92859e-06 4.8196e-06 1.32688e-06" />
            <joint name="r_thumb_mcp" pos="0 0 0" axis="0 1 0" range="-1.047 1.57" actuatorfrcrange="-0.3 0.3" />
            <geom type="mesh" contype="0" conaffinity="0" group="1" density="0" rgba="0.6 0.8 0.9 1" mesh="r_thumb_middle" />
            <geom type="mesh" rgba="0.6 0.8 0.9 1" mesh="r_thumb_middle" contype="1" conaffinity="1" />
            <body name="r_thumb_distal" gravcomp="1" pos="0 -5e-05 0.035">
              <inertial pos="0.000584113 -1.969e-05 0.0149297" quat="0.998214 -0.00602895 -0.0527021 -0.0274855" mass="0.0159" diaginertia="1.38099e-06 1.3339e-06 6.79986e-07" />
              <joint name="r_thumb_ip" pos="0 0 0" axis="0 1 0" range="-1.047 1.57" actuatorfrcrange="-0.3 0.3" />
              <geom type="mesh" contype="0" conaffinity="0" group="1" density="0" rgba="0.6 0.8 0.9 1" mesh="r_thumb_distal" />
              <geom type="mesh" rgba="0.6 0.8 0.9 1" mesh="r_thumb_distal" contype="1" conaffinity="1" />
              <site name="r_thumb_tip" pos="0 0 0.02978" group="3" size="0.002" rgba="1 0 0 1" />
            </body>
          </body>
        </body>
      </body>
      <body name="r_index_finger_proximal" gravcomp="1" pos="-0.00307463 0.025661 0.0984751" quat="0.996267 -0.0693674 -0.016387 -0.0487017">
        <inertial pos="-0.00178137 1.83198e-09 0.00760139" quat="0.706594 -0.0269145 -0.0269145 0.706594" mass="0.0116" diaginertia="9.19684e-07 9.08608e-07 7.88412e-07" />
        <joint name="r_index_finger_mcp_flex" pos="0 0 0" axis="0 1 0" range="-1.047 1.57" actuatorfrcrange="-2 2" armature="0.0005" />
        <geom type="mesh" contype="0" conaffinity="0" group="1" density="0" rgba="0.7 0.7 0.7 1" mesh="r_index_finger_proximal" />
        <geom type="mesh" rgba="0.7 0.7 0.7 1" mesh="r_index_finger_proximal" contype="0" conaffinity="0" />
        <body name="r_index_finger_proximal_abd" gravcomp="1" pos="-0.00120098 0 0.0145" quat="0.707107 0 0 0.707107">
          <inertial pos="8.04675e-08 -7.30404e-07 0.0187994" quat="0.983237 -1.60588e-05 -3.84243e-06 -0.18233" mass="0.0339" diaginertia="7.01589e-06 7.01555e-06 9.1448e-07" />
          <joint name="r_index_finger_mcp_abd" pos="0 0 0" axis="0 -1 0" range="-0.698 0.698" actuatorfrcrange="-0.2 0.2" />
          <geom type="mesh" contype="0" conaffinity="0" group="1" density="0" rgba="0.9 0.8 0.6 1" mesh="r_index_finger_proximal_abd" />
          <geom type="mesh" rgba="0.9 0.8 0.6 1" mesh="r_index_finger_proximal_abd" contype="2" conaffinity="2" />
          <body name="r_index_finger_middle" gravcomp="1" pos="0 0 0.0376" quat="0.707107 0 0 -0.707107">
            <inertial pos="-0.000247887 -5.07335e-08 0.0190348" quat="0.999883 7.82228e-06 0.0152755 0.000297981" mass="0.0212" diaginertia="2.47797e-06 2.40525e-06 6.52478e-07" />
            <joint name="r_index_finger_pip" pos="0 0 0" axis="0 1 0" range="-1.047 2.094" actuatorfrcrange="-0.3 0.3" />
            <geom type="mesh" contype="0" conaffinity="0" group="1" density="0" rgba="0.6 0.8 0.9 1" mesh="r_index_finger_middle" />
            <geom type="mesh" rgba="0.6 0.8 0.9 1" mesh="r_index_finger_middle" contype="1" conaffinity="1" />
            <body name="r_index_finger_distal" gravcomp="1" pos="0 0 0.0295">
              <inertial pos="-2.6809e-05 0.000450223 0.0122088" quat="0.995535 0.0584894 -0.0523628 0.0524081" mass="0.0078" diaginertia="5.687e-07 5.37521e-07 2.69652e-07" />
              <joint name="r_index_finger_dip" pos="0 0 0" axis="0 1 0" range="-1.047 1.57" actuatorfrcrange="-0.3 0.3" />
              <geom type="mesh" contype="0" conaffinity="0" group="1" density="0" rgba="0.6 0.8 0.9 1" mesh="r_index_finger_distal" />
              <geom type="mesh" rgba="0.6 0.8 0.9 1" mesh="r_index_finger_distal" contype="1" conaffinity="1" />
              <site name="r_index_finger_tip" pos="0 0 0.02475" group="3" size="0.002" rgba="1 0 0 1" />
            </body>
          </body>
        </body>
      </body>
      <body name="r_middle_finger_proximal" gravcomp="1" pos="-0.00805284 0.00395219 0.102415" quat="0.999841 0.00552374 -0.0169518 0.000255885">
        <inertial pos="-0.00178137 1.83198e-09 0.00760139" quat="0.706594 -0.0269145 -0.0269145 0.706594" mass="0.0116" diaginertia="9.19684e-07 9.08608e-07 7.88412e-07" />
        <joint name="r_middle_finger_mcp_flex" pos="0 0 0" axis="0 1 0" range="-1.047 1.57" actuatorfrcrange="-2 2" armature="0.0005" />
        <geom type="mesh" contype="0" conaffinity="0" group="1" density="0" rgba="0.7 0.7 0.7 1" mesh="r_middle_finger_proximal" />
        <geom type="mesh" rgba="0.7 0.7 0.7 1" mesh="r_middle_finger_proximal" contype="0" conaffinity="0" />
        <body name="r_middle_finger_proximal_abd" gravcomp="1" pos="-0.00120098 0 0.0145" quat="0.707107 0 0 0.707107">
          <inertial pos="8.04675e-08 -7.30404e-07 0.0187994" quat="0.983237 -1.60588e-05 -3.84243e-06 -0.18233" mass="0.0339" diaginertia="7.01589e-06 7.01555e-06 9.1448e-07" />
          <joint name="r_middle_finger_mcp_abd" pos="0 0 0" axis="0 -1 0" range="-0.698 0.698" actuatorfrcrange="-0.2 0.2" />
          <geom type="mesh" contype="0" conaffinity="0" group="1" density="0" rgba="0.9 0.8 0.6 1" mesh="r_middle_finger_proximal_abd" />
          <geom type="mesh" rgba="0.9 0.8 0.6 1" mesh="r_middle_finger_proximal_abd" contype="2" conaffinity="2" />
          <body name="r_middle_finger_middle" gravcomp="1" pos="0 0 0.0376" quat="0.707107 0 0 -0.707107">
            <inertial pos="-0.000247887 -5.07335e-08 0.0190348" quat="0.999883 7.82228e-06 0.0152755 0.000297981" mass="0.0212" diaginertia="2.47797e-06 2.40525e-06 6.52478e-07" />
            <joint name="r_middle_finger_pip" pos="0 0 0" axis="0 1 0" range="-1.047 2.094" actuatorfrcrange="-0.3 0.3" />
            <geom type="mesh" contype="0" conaffinity="0" group="1" density="0" rgba="0.6 0.8 0.9 1" mesh="r_middle_finger_middle" />
            <geom type="mesh" rgba="0.6 0.8 0.9 1" mesh="r_middle_finger_middle" contype="1" conaffinity="1" />
            <body name="r_middle_finger_distal" gravcomp="1" pos="0 0 0.0295">
              <inertial pos="-2.6809e-05 0.000450223 0.0122088" quat="0.995535 0.0584894 -0.0523628 0.0524081" mass="0.0078" diaginertia="5.687e-07 5.37521e-07 2.69652e-07" />
              <joint name="r_middle_finger_dip" pos="0 0 0" axis="0 1 0" range="-1.047 1.57" actuatorfrcrange="-0.3 0.3" />
              <geom type="mesh" contype="0" conaffinity="0" group="1" density="0" rgba="0.6 0.8 0.9 1" mesh="r_middle_finger_distal" />
              <geom type="mesh" rgba="0.6 0.8 0.9 1" mesh="r_middle_finger_distal" contype="1" conaffinity="1" />
              <site name="r_middle_finger_tip" pos="0 0 0.02475" group="3" size="0.002" rgba="1 0 0 1" />
            </body>
          </body>
        </body>
      </body>
      <body name="r_ring_finger_proximal" gravcomp="1" pos="-0.00534309 -0.0167437 0.0938997" quat="0.996897 0.0709975 -0.00588573 0.0334694">
        <inertial pos="-0.00178137 1.83198e-09 0.00760139" quat="0.706594 -0.0269145 -0.0269145 0.706594" mass="0.0116" diaginertia="9.19684e-07 9.08608e-07 7.88412e-07" />
        <joint name="r_ring_finger_mcp_flex" pos="0 0 0" axis="0 1 0" range="-1.047 1.57" actuatorfrcrange="-2 2" armature="0.0005" />
        <geom type="mesh" contype="0" conaffinity="0" group="1" density="0" rgba="0.7 0.7 0.7 1" mesh="r_ring_finger_proximal" />
        <geom type="mesh" rgba="0.7 0.7 0.7 1" mesh="r_ring_finger_proximal" contype="0" conaffinity="0" />
        <body name="r_ring_finger_proximal_abd" gravcomp="1" pos="-0.00120098 0 0.0145" quat="0.707107 0 0 0.707107">
          <inertial pos="8.04675e-08 -7.30404e-07 0.0187994" quat="0.983237 -1.60588e-05 -3.84243e-06 -0.18233" mass="0.0339" diaginertia="7.01589e-06 7.01555e-06 9.1448e-07" />
          <joint name="r_ring_finger_mcp_abd" pos="0 0 0" axis="0 -1 0" range="-0.698 0.698" actuatorfrcrange="-0.2 0.2" />
          <geom type="mesh" contype="0" conaffinity="0" group="1" density="0" rgba="0.9 0.8 0.6 1" mesh="r_ring_finger_proximal_abd" />
          <geom type="mesh" rgba="0.9 0.8 0.6 1" mesh="r_ring_finger_proximal_abd" contype="2" conaffinity="2" />
          <body name="r_ring_finger_middle" gravcomp="1" pos="0 0 0.0376" quat="0.707107 0 0 -0.707107">
            <inertial pos="-0.000247887 -5.07335e-08 0.0190348" quat="0.999883 7.82228e-06 0.0152755 0.000297981" mass="0.0212" diaginertia="2.47797e-06 2.40525e-06 6.52478e-07" />
            <joint name="r_ring_finger_pip" pos="0 0 0" axis="0 1 0" range="-1.047 2.094" actuatorfrcrange="-0.3 0.3" />
            <geom type="mesh" contype="0" conaffinity="0" group="1" density="0" rgba="0.6 0.8 0.9 1" mesh="r_ring_finger_middle" />
            <geom type="mesh" rgba="0.6 0.8 0.9 1" mesh="r_ring_finger_middle" contype="1" conaffinity="1" />
            <body name="r_ring_finger_distal" gravcomp="1" pos="0 0 0.0295">
              <inertial pos="-2.6809e-05 0.000450223 0.0122088" quat="0.995535 0.0584894 -0.0523628 0.0524081" mass="0.0078" diaginertia="5.687e-07 5.37521e-07 2.69652e-07" />
              <joint name="r_ring_finger_dip" pos="0 0 0" axis="0 1 0" range="-1.047 1.57" actuatorfrcrange="-0.3 0.3" />
              <geom type="mesh" contype="0" conaffinity="0" group="1" density="0" rgba="0.6 0.8 0.9 1" mesh="r_ring_finger_distal" />
              <geom type="mesh" rgba="0.6 0.8 0.9 1" mesh="r_ring_finger_distal" contype="1" conaffinity="1" />
              <site name="r_ring_finger_tip" pos="0 0 0.02475" group="3" size="0.002" rgba="1 0 0 1" />
            </body>
          </body>
        </body>
      </body>
      <body name="r_pinky_proximal" gravcomp="1" pos="-0.00048421 -0.0343506 0.0837961" quat="0.989991 0.124816 -0.006386 0.0655637">
        <inertial pos="-0.00178136 -2.12647e-07 0.00760145" quat="0.70667 -0.0268963 -0.0269307 0.706519" mass="0.0116" diaginertia="9.19664e-07 9.08603e-07 7.88413e-07" />
        <joint name="r_pinky_mcp_flex" pos="0 0 0" axis="0 1 0" range="-1.047 1.57" actuatorfrcrange="-2 2" armature="0.0005" />
        <geom type="mesh" contype="0" conaffinity="0" group="1" density="0" rgba="0.7 0.7 0.7 1" mesh="r_pinky_proximal" />
        <geom type="mesh" rgba="0.7 0.7 0.7 1" mesh="r_pinky_proximal" contype="0" conaffinity="0" />
        <body name="r_pinky_proximal_abd" gravcomp="1" pos="-0.00120098 0 0.0145" quat="0.70712 0 0 0.707094">
          <inertial pos="1.55647e-06 -5.4532e-07 0.016785" quat="0.647368 -3.02081e-05 7.77124e-06 0.762177" mass="0.0304" diaginertia="5.38014e-06 5.37944e-06 8.1771e-07" />
          <joint name="r_pinky_mcp_abd" pos="0 0 0" axis="0 -1 0" range="-0.698 0.698" actuatorfrcrange="-0.2 0.2" />
          <geom type="mesh" contype="0" conaffinity="0" group="1" density="0" rgba="0.9 0.8 0.6 1" mesh="r_pinky_proximal_abd" />
          <geom type="mesh" rgba="0.9 0.8 0.6 1" mesh="r_pinky_proximal_abd" contype="2" conaffinity="2" />
          <body name="r_pinky_middle" gravcomp="1" pos="0.0001 0 0.0336" quat="0.70712 0 0 -0.707094">
            <inertial pos="-0.000264491 -3.23236e-07 0.0178807" quat="0.999872 3.90058e-06 0.0159651 0.000317107" mass="0.0188" diaginertia="2.05957e-06 1.98647e-06 5.84911e-07" />
            <joint name="r_pinky_pip" pos="0 0 0" axis="0 1 0" range="-1.047 2.094" actuatorfrcrange="-0.3 0.3" />
            <geom type="mesh" contype="0" conaffinity="0" group="1" density="0" rgba="0.6 0.8 0.9 1" mesh="r_pinky_middle" />
            <geom type="mesh" rgba="0.6 0.8 0.9 1" mesh="r_pinky_middle" contype="1" conaffinity="1" />
            <body name="r_pinky_distal" gravcomp="1" pos="0 0 0.0275">
              <inertial pos="-0.000344833 0.000450223 0.012204" quat="0.994769 0.0578017 -0.0653262 0.0531671" mass="0.0078" diaginertia="5.687e-07 5.37521e-07 2.69652e-07" />
              <joint name="r_pinky_dip" pos="0 0 0" axis="0 1 0" range="-1.047 1.57" actuatorfrcrange="-0.3 0.3" />
              <geom type="mesh" contype="0" conaffinity="0" group="1" density="0" rgba="0.6 0.8 0.9 1" mesh="r_pinky_distal" />
              <geom type="mesh" rgba="0.6 0.8 0.9 1" mesh="r_pinky_distal" contype="1" conaffinity="1" />
              <site name="r_pinky_tip" pos="0 0 0.024755" group="3" size="0.002" rgba="1 0 0 1" />
            </body>
          </body>
        </body>
      </body>
    </body>
  </worldbody>
  <actuator>
    <position name="right_finger1_joint1_actuator" joint="r_thumb_cmc_flex" kp="0.40844710645048043" kv="0.020882010257063675" ctrlrange="-1.187 1.291" forcerange="-0.6 0.6" />
    <position name="right_finger1_joint2_actuator" joint="r_thumb_cmc_abd" kp="0.6858601063643346" kv="0.030610939996373314" ctrlrange="-1.484 0.698" forcerange="-0.6 0.6" />
    <position name="right_finger1_joint3_actuator" joint="r_thumb_mcp" kp="0.2391112196099482" kv="0.010181475050560962" ctrlrange="-1.047 1.57" forcerange="-0.3 0.3" />
    <position name="right_finger1_joint4_actuator" joint="r_thumb_ip" kp="0.20736128319711747" kv="0.00909698844675045" ctrlrange="-1.047 1.57" forcerange="-0.3 0.3" />
    <position name="right_finger2_joint1_actuator" joint="r_index_finger_mcp_flex" kp="0.37352218155860073" kv="0.01882274330029718" ctrlrange="-1.047 1.57" forcerange="-2 2" />
    <position name="right_finger2_joint2_actuator" joint="r_index_finger_mcp_abd" kp="0.45592448909027794" kv="0.019798167597016643" ctrlrange="-0.698 0.698" forcerange="-0.2 0.2" />
    <position name="right_finger2_joint3_actuator" joint="r_index_finger_pip" kp="0.24368366649522863" kv="0.010477031953162727" ctrlrange="-1.047 2.094" forcerange="-0.3 0.3" />
    <position name="right_finger2_joint4_actuator" joint="r_index_finger_dip" kp="0.18026971340925335" kv="0.008240212147903584" ctrlrange="-1.047 1.57" forcerange="-0.3 0.3" />
    <position name="right_finger3_joint1_actuator" joint="r_middle_finger_mcp_flex" kp="0.3687093483646485" kv="0.01848622487024593" ctrlrange="-1.047 1.57" forcerange="-2 2" />
    <position name="right_finger3_joint2_actuator" joint="r_middle_finger_mcp_abd" kp="0.4164253443634641" kv="0.018032947229953678" ctrlrange="-0.698 0.698" forcerange="-0.2 0.2" />
    <position name="right_finger3_joint3_actuator" joint="r_middle_finger_pip" kp="0.22218607502059182" kv="0.009592200014076666" ctrlrange="-1.047 2.094" forcerange="-0.3 0.3" />
    <position name="right_finger3_joint4_actuator" joint="r_middle_finger_dip" kp="0.19427606072023446" kv="0.009152994605972402" ctrlrange="-1.047 1.57" forcerange="-0.3 0.3" />
    <position name="right_finger4_joint1_actuator" joint="r_ring_finger_mcp_flex" kp="0.35718151495111794" kv="0.018376606800780005" ctrlrange="-1.047 1.57" forcerange="-2 2" />
    <position name="right_finger4_joint2_actuator" joint="r_ring_finger_mcp_abd" kp="0.42977315313086895" kv="0.01867700966212433" ctrlrange="-0.698 0.698" forcerange="-0.2 0.2" />
    <position name="right_finger4_joint3_actuator" joint="r_ring_finger_pip" kp="0.24930151196247122" kv="0.01059512121009555" ctrlrange="-1.047 2.094" forcerange="-0.3 0.3" />
    <position name="right_finger4_joint4_actuator" joint="r_ring_finger_dip" kp="0.2285032688178066" kv="0.009917602877441107" ctrlrange="-1.047 1.57" forcerange="-0.3 0.3" />
    <position name="right_finger5_joint1_actuator" joint="r_pinky_mcp_flex" kp="0.3655325975433942" kv="0.018616960278988272" ctrlrange="-1.047 1.57" forcerange="-2 2" />
    <position name="right_finger5_joint2_actuator" joint="r_pinky_mcp_abd" kp="0.41393113081120425" kv="0.018732177029667153" ctrlrange="-0.698 0.698" forcerange="-0.2 0.2" />
    <position name="right_finger5_joint3_actuator" joint="r_pinky_pip" kp="0.22729367621965954" kv="0.00951005441616486" ctrlrange="-1.047 2.094" forcerange="-0.3 0.3" />
    <position name="right_finger5_joint4_actuator" joint="r_pinky_dip" kp="0.1964723550341816" kv="0.009017295241756363" ctrlrange="-1.047 1.57" forcerange="-0.3 0.3" />
  </actuator>
  <contact>
    <exclude body1="r_base_link" body2="r_thumb_distal" />
    <exclude body1="r_base_link" body2="r_thumb_middle" />
    <exclude body1="r_index_finger_distal" body2="r_middle_finger_distal" />
    <exclude body1="r_index_finger_distal" body2="r_middle_finger_middle" />
    <exclude body1="r_index_finger_distal" body2="r_ring_finger_distal" />
    <exclude body1="r_index_finger_distal" body2="r_ring_finger_middle" />
    <exclude body1="r_index_finger_distal" body2="r_thumb_middle" />
    <exclude body1="r_index_finger_distal" body2="r_base_link" />
    <exclude body1="r_index_finger_middle" body2="r_middle_finger_distal" />
    <exclude body1="r_index_finger_middle" body2="r_middle_finger_middle" />
    <exclude body1="r_index_finger_middle" body2="r_ring_finger_distal" />
    <exclude body1="r_index_finger_middle" body2="r_ring_finger_middle" />
    <exclude body1="r_index_finger_proximal_abd" body2="r_middle_finger_proximal_abd" />
    <exclude body1="r_index_finger_proximal_abd" body2="r_thumb_proximal_abd" />
    <exclude body1="r_middle_finger_distal" body2="r_pinky_distal" />
    <exclude body1="r_middle_finger_distal" body2="r_pinky_middle" />
    <exclude body1="r_middle_finger_distal" body2="r_ring_finger_distal" />
    <exclude body1="r_middle_finger_distal" body2="r_ring_finger_middle" />
    <exclude body1="r_middle_finger_distal" body2="r_thumb_middle" />
    <exclude body1="r_middle_finger_distal" body2="r_base_link" />
    <exclude body1="r_middle_finger_middle" body2="r_pinky_distal" />
    <exclude body1="r_middle_finger_middle" body2="r_pinky_middle" />
    <exclude body1="r_middle_finger_middle" body2="r_ring_finger_distal" />
    <exclude body1="r_middle_finger_middle" body2="r_ring_finger_middle" />
    <exclude body1="r_middle_finger_proximal_abd" body2="r_ring_finger_proximal_abd" />
    <exclude body1="r_pinky_distal" body2="r_ring_finger_distal" />
    <exclude body1="r_pinky_distal" body2="r_ring_finger_middle" />
    <exclude body1="r_pinky_distal" body2="r_base_link" />
    <exclude body1="r_pinky_middle" body2="r_ring_finger_distal" />
    <exclude body1="r_pinky_middle" body2="r_ring_finger_middle" />
    <exclude body1="r_pinky_proximal_abd" body2="r_ring_finger_proximal_abd" />
    <exclude body1="r_ring_finger_distal" body2="r_base_link" />
  </contact>
</mujoco>